# 🔧 CORREÇÃO DO BUG GRAPHITI-TURSO

## 🐛 Problema Identificado

**Bug:** `'bool' object is not callable` na função `add_episode`

**Causa Raiz:** Conflito de nomes na função `add_episode`:
- Parâmetro da função: `sync_to_turso: bool = True`  
- Função interna sendo chamada: `sync_to_turso(episode_data)`

Na linha 309-310, o código tentava chamar `sync_to_turso()` como função, mas `sync_to_turso` já era uma variável booleana (parâmetro), causando o erro.

## ✅ Correção Aplicada

**Arquivo:** `graphiti_mcp_turso_integrated.py`

### Mudanças:

1. **Renomeada função:** `sync_to_turso()` → `sync_episode_to_turso()`
2. **Atualizada chamada:** linha 310

**Antes:**
```python
# Linha 196
async def sync_to_turso(episode_data: Dict[str, Any]):

# Linha 310  
await sync_to_turso({...})  # ❌ Conflito com parâmetro bool
```

**Depois:**
```python
# Linha 196
async def sync_episode_to_turso(episode_data: Dict[str, Any]):

# Linha 310
await sync_episode_to_turso({...})  # ✅ Sem conflito
```

## 🎯 Status da Correção

- ✅ Código corrigido
- ⚠️ Servidor precisa ser reiniciado
- ⏳ Teste pendente após reinicialização

## 🚀 Próximos Passos

1. Reiniciar o servidor MCP Graphiti-Turso
2. Testar a função `add_episode` novamente
3. Validar que não há mais erros
4. Confirmar que episódios são criados sem mensagens de erro

---
*Correção aplicada em 11 de Agosto de 2025*
*Bug: Conflito de nomes entre parâmetro e função*